ERROR:root:Command failed
Traceback (most recent call last):
  File "/home/eren/ftg/friendly-telegram/main.py", line 129, in handle_command
    await coro
  File "<string>", line 60, in download
  File "<string>", line 67, in git_commit
  File "/usr/local/lib/python3.8/codecs.py", line 322, in decode
    (result, consumed) = self._buffer_decode(data, self.errors, final)
UnicodeDecodeError: 'utf-8' codec can't decode byte 0x96 in position 10: invalid start byte
ERROR:telethon.client.updates:Unhandled exception on functools.partial(<function handle_command at 0x7f58dee48550>, <friendly-telegram.loader.Modules object at 0x7f58dbb93e80>, <friendly-telegram.database.frontend.Database object at 0x7f58dbbfd280>)
Traceback (most recent call last):
  File "/home/eren/ftg/friendly-telegram/main.py", line 133, in handle_command
    await message.edit("<code>Request failed! Request was " + message.message
  File "/usr/local/lib/python3.8/site-packages/telethon/tl/custom/message.py", line 726, in edit
    return await self._client.edit_message(
  File "/usr/local/lib/python3.8/site-packages/telethon/client/messages.py", line 1034, in edit_message
    msg = self._get_response_message(request, await self(request), entity)
  File "/usr/local/lib/python3.8/site-packages/telethon/client/users.py", line 74, in __call__
    result = await future
telethon.errors.rpcerrorlist.MessageIdInvalidError: The specified message ID is invalid or you can't do that operation on such message (caused by EditMessageRequest)

During handling of the above exception, another exception occurred:

Traceback (most recent call last):
  File "/usr/local/lib/python3.8/site-packages/telethon/client/updates.py", line 422, in _dispatch_update
    await callback(event)
  File "/home/eren/ftg/friendly-telegram/main.py", line 137, in handle_command
    raise e
  File "/home/eren/ftg/friendly-telegram/main.py", line 129, in handle_command
    await coro
  File "<string>", line 60, in download
  File "<string>", line 67, in git_commit
  File "/usr/local/lib/python3.8/codecs.py", line 322, in decode
    (result, consumed) = self._buffer_decode(data, self.errors, final)
UnicodeDecodeError: 'utf-8' codec can't decode byte 0x96 in position 10: invalid start byte
ERROR:root:Command failed
Traceback (most recent call last):
  File "/home/eren/ftg/friendly-telegram/main.py", line 129, in handle_command
    await coro
  File "<string>", line 60, in download
  File "<string>", line 71, in git_commit
  File "/usr/local/lib/python3.8/site-packages/github/MainClass.py", line 290, in get_repo
    headers, data = self.__requester.requestJsonAndCheck(
  File "/usr/local/lib/python3.8/site-packages/github/Requester.py", line 268, in requestJsonAndCheck
    return self.__check(*self.requestJson(verb, url, parameters, headers, input, self.__customConnection(url)))
  File "/usr/local/lib/python3.8/site-packages/github/Requester.py", line 279, in __check
    raise self.__createException(status, responseHeaders, output)
github.GithubException.UnknownObjectException: 404 {"message": "Not Found", "documentation_url": "https://developer.github.com/v3/repos/#get"}
ERROR:telethon.client.updates:Unhandled exception on functools.partial(<function handle_command at 0x7f58dee48550>, <friendly-telegram.loader.Modules object at 0x7f58dbb93e80>, <friendly-telegram.database.frontend.Database object at 0x7f58dbbfd280>)
Traceback (most recent call last):
  File "/home/eren/ftg/friendly-telegram/main.py", line 133, in handle_command
    await message.edit("<code>Request failed! Request was " + message.message
  File "/usr/local/lib/python3.8/site-packages/telethon/tl/custom/message.py", line 726, in edit
    return await self._client.edit_message(
  File "/usr/local/lib/python3.8/site-packages/telethon/client/messages.py", line 1034, in edit_message
    msg = self._get_response_message(request, await self(request), entity)
  File "/usr/local/lib/python3.8/site-packages/telethon/client/users.py", line 74, in __call__
    result = await future
telethon.errors.rpcerrorlist.MessageIdInvalidError: The specified message ID is invalid or you can't do that operation on such message (caused by EditMessageRequest)

During handling of the above exception, another exception occurred:

Traceback (most recent call last):
  File "/usr/local/lib/python3.8/site-packages/telethon/client/updates.py", line 422, in _dispatch_update
    await callback(event)
  File "/home/eren/ftg/friendly-telegram/main.py", line 137, in handle_command
    raise e
  File "/home/eren/ftg/friendly-telegram/main.py", line 129, in handle_command
    await coro
  File "<string>", line 60, in download
  File "<string>", line 71, in git_commit
  File "/usr/local/lib/python3.8/site-packages/github/MainClass.py", line 290, in get_repo
    headers, data = self.__requester.requestJsonAndCheck(
  File "/usr/local/lib/python3.8/site-packages/github/Requester.py", line 268, in requestJsonAndCheck
    return self.__check(*self.requestJson(verb, url, parameters, headers, input, self.__customConnection(url)))
  File "/usr/local/lib/python3.8/site-packages/github/Requester.py", line 279, in __check
    raise self.__createException(status, responseHeaders, output)
github.GithubException.UnknownObjectException: 404 {"message": "Not Found", "documentation_url": "https://developer.github.com/v3/repos/#get"}